<?xml version="1.0" ?>
<!-- =================================================================================== -->
<!-- |    This document was autogenerated by xacro from /home/user1/catkin_ws/src/iggy_description/urdf/iggy_minimal.urdf.xacro | -->
<!-- |    EDITING THIS FILE BY HAND IS NOT RECOMMENDED                                 | -->
<!-- =================================================================================== -->
<!--
rosrun xacro xacro.py -o iggy_minimal.urdf `rospack find iggy_description`/urdf/iggy_minimal.urdf.xacro
check_urdf iggy_minimal.urdf
urdf_to_graphiz iggy_minimal.urdf
evince iggy_minimal.pdf


-->
<robot name="iggy" xmlns:controller="http://playerstage.sourceforge.net/gazebo/xmlschema/#controller" xmlns:interface="http://playerstage.sourceforge.net/gazebo/xmlschema/#interface" xmlns:xacro="http://www.ros.org/wiki/xacro">
  <!-- TODO UPDATE -->
  <!-- TODO UPDATE -->
  <!-- TODO UPDATE -->
  <!-- TODO UPDATE -->
  <!-- TODO UPDATE -->
  <!-- TODO UPDATE -->
  <!-- TODO UPDATE -->
  <!-- TODO UPDATE -->
  <material name="dark_grey">
    <color rgba="0.2 0.2 0.2 1.0"/>
  </material>
  <material name="light_grey">
    <color rgba="0.4 0.4 0.4 1.0"/>
  </material>
  <material name="yellow">
    <color rgba="0.8 0.8 0.0 1.0"/>
  </material>
  <material name="black">
    <color rgba="0.15 0.15 0.15 1.0"/>
  </material>
  <!-- TODO Create Caster to replace front wheels  -->
  <link name="front_left_wheel_link">
    <visual>
      <origin rpy="1.57079632679 0 0" xyz="0 0 0"/>
      <geometry>
        <mesh filename="package://iggy_description/meshes/jackal-wheel.stl"/>
      </geometry>
      <material name="black"/>
    </visual>
    <collision>
      <origin rpy="1.57079632679 0 0" xyz="0 0 0"/>
      <geometry>
        <cylinder length="0.04" radius="0.098"/>
      </geometry>
    </collision>
    <inertial>
      <origin rpy="0 0 0" xyz="0 0 0"/>
      <mass value="0.477"/>
      <inertia ixx="0.0013" ixy="0" ixz="0" iyy="0.0024" iyz="0" izz="0.0013"/>
    </inertial>
  </link>
  <gazebo reference="front_left_wheel_link">
    <material>Gazebo/DarkGrey</material>
  </gazebo>
  <joint name="front_left_wheel" type="continuous">
    <parent link="chassis_link"/>
    <child link="front_left_wheel_link"/>
    <origin rpy="0 0 0" xyz="0.131 0.187795 0.0345"/>
    <axis xyz="0 1 0"/>
  </joint>
  <!-- Create a transmission for each wheel -->
  <transmission name="front_left_wheel_trans">
    <type>transmission_interface/SimpleTransmission</type>
    <joint name="front_left_wheel">
      <hardwareInterface>VelocityJointInterface</hardwareInterface>
    </joint>
    <actuator name="front_left_actuator">
      <mechanicalReduction>1</mechanicalReduction>
    </actuator>
  </transmission>
  <link name="front_right_wheel_link">
    <visual>
      <origin rpy="1.57079632679 0 0" xyz="0 0 0"/>
      <geometry>
        <mesh filename="package://iggy_description/meshes/jackal-wheel.stl"/>
      </geometry>
      <material name="black"/>
    </visual>
    <collision>
      <origin rpy="1.57079632679 0 0" xyz="0 0 0"/>
      <geometry>
        <cylinder length="0.04" radius="0.098"/>
      </geometry>
    </collision>
    <inertial>
      <origin rpy="0 0 0" xyz="0 0 0"/>
      <mass value="0.477"/>
      <inertia ixx="0.0013" ixy="0" ixz="0" iyy="0.0024" iyz="0" izz="0.0013"/>
    </inertial>
  </link>
  <gazebo reference="front_right_wheel_link">
    <material>Gazebo/DarkGrey</material>
  </gazebo>
  <joint name="front_right_wheel" type="continuous">
    <parent link="chassis_link"/>
    <child link="front_right_wheel_link"/>
    <origin rpy="0 0 0" xyz="0.131 -0.187795 0.0345"/>
    <axis xyz="0 1 0"/>
  </joint>
  <!-- Create a transmission for each wheel -->
  <transmission name="front_right_wheel_trans">
    <type>transmission_interface/SimpleTransmission</type>
    <joint name="front_right_wheel">
      <hardwareInterface>VelocityJointInterface</hardwareInterface>
    </joint>
    <actuator name="front_right_actuator">
      <mechanicalReduction>1</mechanicalReduction>
    </actuator>
  </transmission>
  <link name="rear_left_wheel_link">
    <visual>
      <origin rpy="1.57079632679 0 0" xyz="0 0 0"/>
      <geometry>
        <mesh filename="package://iggy_description/meshes/jackal-wheel.stl"/>
      </geometry>
      <material name="black"/>
    </visual>
    <collision>
      <origin rpy="1.57079632679 0 0" xyz="0 0 0"/>
      <geometry>
        <cylinder length="0.04" radius="0.098"/>
      </geometry>
    </collision>
    <inertial>
      <origin rpy="0 0 0" xyz="0 0 0"/>
      <mass value="0.477"/>
      <inertia ixx="0.0013" ixy="0" ixz="0" iyy="0.0024" iyz="0" izz="0.0013"/>
    </inertial>
  </link>
  <gazebo reference="rear_left_wheel_link">
    <material>Gazebo/DarkGrey</material>
  </gazebo>
  <joint name="rear_left_wheel" type="continuous">
    <parent link="chassis_link"/>
    <child link="rear_left_wheel_link"/>
    <origin rpy="0 0 0" xyz="-0.131 0.187795 0.0345"/>
    <axis xyz="0 1 0"/>
  </joint>
  <!-- Create a transmission for each wheel -->
  <transmission name="rear_left_wheel_trans">
    <type>transmission_interface/SimpleTransmission</type>
    <joint name="rear_left_wheel">
      <hardwareInterface>VelocityJointInterface</hardwareInterface>
    </joint>
    <actuator name="rear_left_actuator">
      <mechanicalReduction>1</mechanicalReduction>
    </actuator>
  </transmission>
  <link name="rear_right_wheel_link">
    <visual>
      <origin rpy="1.57079632679 0 0" xyz="0 0 0"/>
      <geometry>
        <mesh filename="package://iggy_description/meshes/jackal-wheel.stl"/>
      </geometry>
      <material name="black"/>
    </visual>
    <collision>
      <origin rpy="1.57079632679 0 0" xyz="0 0 0"/>
      <geometry>
        <cylinder length="0.04" radius="0.098"/>
      </geometry>
    </collision>
    <inertial>
      <origin rpy="0 0 0" xyz="0 0 0"/>
      <mass value="0.477"/>
      <inertia ixx="0.0013" ixy="0" ixz="0" iyy="0.0024" iyz="0" izz="0.0013"/>
    </inertial>
  </link>
  <gazebo reference="rear_right_wheel_link">
    <material>Gazebo/DarkGrey</material>
  </gazebo>
  <joint name="rear_right_wheel" type="continuous">
    <parent link="chassis_link"/>
    <child link="rear_right_wheel_link"/>
    <origin rpy="0 0 0" xyz="-0.131 -0.187795 0.0345"/>
    <axis xyz="0 1 0"/>
  </joint>
  <!-- Create a transmission for each wheel -->
  <transmission name="rear_right_wheel_trans">
    <type>transmission_interface/SimpleTransmission</type>
    <joint name="rear_right_wheel">
      <hardwareInterface>VelocityJointInterface</hardwareInterface>
    </joint>
    <actuator name="rear_right_actuator">
      <mechanicalReduction>1</mechanicalReduction>
    </actuator>
  </transmission>
  <link name="base_link"/>
  <joint name="base_link_joint" type="fixed">
    <origin rpy="0 0 0" xyz="0 0 0"/>
    <parent link="base_link"/>
    <child link="chassis_link"/>
  </joint>
  <link name="chassis_link">
    <visual>
      <origin rpy="1.57079632679 0 1.57079632679" xyz="0 0 -0.0655"/>
      <geometry>
        <mesh filename="package://iggy_description/meshes/jackal-base.stl"/>
      </geometry>
      <material name="dark_grey"/>
    </visual>
    <collision>
      <origin xyz="0 0 0.092"/>
      <geometry>
        <box size="0.914 0.609 0.184"/>
      </geometry>
    </collision>
    <inertial>
      <!-- Center of mass -->
      <origin rpy="0 0 0" xyz="0.012  0.002 0.067"/>
      <mass value="16.523"/>
      <!-- Moments of inertia: ( chassis without wheels ) -->
      <inertia ixx="0.3136" ixy="-0.0008" ixz="0.0164" iyy="0.3922" iyz="-0.0009" izz="0.4485"/>
    </inertial>
  </link>
  <!-- TODO IGGY does not have fenders. What to do with this?? -->
  <link name="fenders_link">
    <visual>
      <origin rpy="1.57079632679 0 1.57079632679" xyz="0 0 -0.0655"/>
      <geometry>
        <mesh filename="package://iggy_description/meshes/jackal-fenders.stl"/>
      </geometry>
      <material name="yellow"/>
    </visual>
  </link>
  <joint name="fenders_joint" type="fixed">
    <parent link="chassis_link"/>
    <child link="fenders_link"/>
  </joint>
  <!-- TODO: Make this internal_imu_link or something, and use a mixed-in xacro
       to supply the joint between it and imu_link. This is important so that imu_link
       always points to the "active" IMU. When an upgrade IMU is connected, the
       internal_imu_link should remain, but imu_link should point to the upgrade one. -->
  <link name="imu_link">
    <inertial>
      <mass value="0.001"/>
      <origin rpy="0 0 0" xyz="0 0 0"/>
      <inertia ixx="1e-09" ixy="0.0" ixz="0.0" iyy="1e-09" iyz="0.0" izz="1e-09"/>
    </inertial>
  </link>
  <joint name="imu_joint" type="fixed">
    <parent link="chassis_link"/>
    <child link="imu_link"/>
  </joint>
  <!-- TODO: Same note as applies to imu_link -->
  <link name="navsat_link">
    <visual>
      <geometry>
        <cylinder length="0.016" radius="0.026"/>
      </geometry>
      <origin xyz="0 0 0.008"/>
      <material name="black"/>
    </visual>
  </link>
  <joint name="navsat_joint" type="fixed">
    <parent link="chassis_link"/>
    <child link="navsat_link"/>
    <origin xyz="-0.180 0.126 0.1815"/>
  </joint>
  <link name="mid_mount"/>
  <joint name="mid_mount_joint" type="fixed">
    <parent link="chassis_link"/>
    <child link="mid_mount"/>
    <origin xyz="0 0 0.184"/>
  </joint>
  <link name="rear_mount"/>
  <joint name="rear_mount_joint" type="fixed">
    <parent link="mid_mount"/>
    <child link="rear_mount"/>
    <origin xyz="-0.12 0 0"/>
  </joint>
  <link name="front_mount"/>
  <joint name="front_mount_joint" type="fixed">
    <parent link="mid_mount"/>
    <child link="front_mount"/>
    <origin xyz="0.12 0 0"/>
  </joint>
  <!-- Bring in simulation data for Gazebo. -->
  <!--  <gazebo>
    <plugin name="gazebo_ros_control" filename="libgazebo_ros_control.so">
      <robotNamespace>/iggy</robotNamespace>
    </plugin>
  </gazebo> -->
  <gazebo>
    <!-- TODO: make custom plugin for this that doesn't require an imu
        <plugin name="diffdrive_plugin" filename="libDiffDrivePlugin.so">                
                <alwaysOn>true</alwaysOn>
                <updateRate>50.0</updateRate>
                <left_joint>rear_left_wheel_link</left_joint>
                <right_joint>rear_right_wheel_link</right_joint>
                <wheelSeparation>${wheelbase}</wheelSeparation>
                <wheelDiameter>${wheel_radius*2}</wheelDiameter>
                <torque>50000</torque>
                <interface:position name="position_iface_2"/>  
                <robotNamespace>/iggy</robotNamespace>
                <robotBaseFrame>base_link</robotBaseFrame>
                <commandTopic>cmd_vel</commandTopic>
                <publishOdometryTf>1</publishOdometryTf>
                <publishOdometryMsg>1</publishOdometryMsg>
                <odometryTopic>odom</odometryTopic>
        </plugin> -->
    <plugin filename="libgazebo_ros_diff_drive.so" name="diffdrive_plugin">
      <alwaysOn>true</alwaysOn>
      <updateRate>50.0</updateRate>
      <leftJoint>rear_left_wheel</leftJoint>
      <rightJoint>rear_right_wheel</rightJoint>
      <wheelSeparation>0.262</wheelSeparation>
      <wheelDiameter>0.196</wheelDiameter>
      <wheelTorque>5000</wheelTorque>
      <publishWheelTF>false</publishWheelTF>
      <publishWheelJointState>false</publishWheelJointState>
      <wheelAcceleration>0</wheelAcceleration>
      <rosDebugLevel>4</rosDebugLevel>
      <robotNamespace/>
      <commandTopic>cmd_vel</commandTopic>
      <odometryTopic>odom</odometryTopic>
      <odometryFrame>odom</odometryFrame>
      <robotBaseFrame>base_link</robotBaseFrame>
    </plugin>
    <plugin filename="libgazebo_ros_p3d.so" name="p3d_base_controller">
      <alwaysOn>true</alwaysOn>
      <updateRate>50.0</updateRate>
      <bodyName>base_link</bodyName>
      <topicName>ground_truth/state</topicName>
      <gaussianNoise>0.01</gaussianNoise>
      <frameName>world</frameName>
      <xyzOffsets>0 0 0</xyzOffsets>
      <rpyOffsets>0 0 0</rpyOffsets>
    </plugin>
  </gazebo>
  <gazebo>
    <plugin filename="libhector_gazebo_ros_imu.so" name="imu_controller">
      <robotNamespace>/iggy</robotNamespace>
      <updateRate>50.0</updateRate>
      <bodyName>imu_link</bodyName>
      <topicName>imu/data</topicName>
      <accelDrift>0.005 0.005 0.005</accelDrift>
      <accelGaussianNoise>0.005 0.005 0.005</accelGaussianNoise>
      <rateDrift>0.005 0.005 0.005 </rateDrift>
      <rateGaussianNoise>0.005 0.005 0.005 </rateGaussianNoise>
      <headingDrift>0.005</headingDrift>
      <headingGaussianNoise>0.005</headingGaussianNoise>
    </plugin>
  </gazebo>
  <gazebo>
    <plugin filename="libhector_gazebo_ros_gps.so" name="gps_controller">
      <updateRate>40</updateRate>
      <robotNamespace>/iggy</robotNamespace>
      <bodyName>navsat_link</bodyName>
      <frameId>base_link</frameId>
      <topicName>navsat/fix</topicName>
      <velocityTopicName>snavsat/vel</velocityTopicName>
      <referenceLatitude>49.9</referenceLatitude>
      <referenceLongitude>8.9</referenceLongitude>
      <referenceHeading>0</referenceHeading>
      <referenceAltitude>0</referenceAltitude>
      <drift>0.0001 0.0001 0.0001</drift>
    </plugin>
  </gazebo>
  <gazebo reference="base_link">
    <turnGravityOff>false</turnGravityOff>
  </gazebo>
  <gazebo reference="chassis_link">
    <material>Gazebo/DarkGrey</material>
    <turnGravityOff>false</turnGravityOff>
  </gazebo>
  <gazebo reference="imu_link">
    <turnGravityOff>false</turnGravityOff>
  </gazebo>
  <gazebo reference="navsat_link">
    <material>Gazebo/DarkGrey</material>
    <turnGravityOff>false</turnGravityOff>
  </gazebo>
  <gazebo reference="fenders_link">
    <material>Gazebo/Yellow</material>
    <turnGravityOff>false</turnGravityOff>
  </gazebo>
</robot>
